print("initialized schematics")

--[[stupid transcoder thing
local test = minetest.register_schematic(minetest.get_modpath("schematics") .. "/schematics/classic.mts")

local transcoded = minetest.serialize_schematic(test, "lua", "")

local mod_storage = minetest.get_mod_storage()

mod_storage:set_string("schem", transcoded)
]]--

--this is transcoded from mcl_core_oak_classic.mts from mineclone2

tree_schem = {
size = {x=5, y=8, z=5},
yslice_prob = {{ypos=0, prob=254},{ypos=1, prob=126},{ypos=2, prob=254},{ypos=3, prob=254},{ypos=4, prob=254},{ypos=5, prob=254},{ypos=6, prob=254},{ypos=7, prob=254}},
data = {
    {name="air", prob=0, param2=0},{name="air", prob=0, param2=0},{name="air", prob=0, param2=0},{name="air", prob=0, param2=0},{name="air", prob=0, param2=0},{name="air", prob=0, param2=0},{name="air", prob=0, param2=0},{name="air", prob=0, param2=0},{name="air", prob=0, param2=0},{name="air", prob=0, param2=0},{name="air", prob=0, param2=0},{name="air", prob=0, param2=0},{name="air", prob=0, param2=0},{name="air", prob=0, param2=0},{name="air", prob=0, param2=0},{name="air", prob=0, param2=0},{name="air", prob=0, param2=0},{name="air", prob=0, param2=0},{name="air", prob=0, param2=0},{name="air", prob=0, param2=0},{name="air", prob=0, param2=0},{name="nodes:leaves", prob=214, param2=0},{name="nodes:leaves", prob=254, param2=0},{name="nodes:leaves", prob=214, param2=0},{name="air", prob=0, param2=0},{name="air", prob=0, param2=0},{name="nodes:leaves", prob=254, param2=0},{name="nodes:leaves", prob=254, param2=0},{name="nodes:leaves", prob=254, param2=0},{name="air", prob=0, param2=0},{name="air", prob=0, param2=0},{name="air", prob=0, param2=0},{name="air", prob=0, param2=0},{name="air", prob=0, param2=0},{name="air", prob=0, param2=0},{name="air", prob=0, param2=0},{name="air", prob=0, param2=0},{name="air", prob=0, param2=0},{name="air", prob=0, param2=0},{name="air", prob=0, param2=0},{name="air", prob=0, param2=0},{name="air", prob=0, param2=0},{name="air", prob=0, param2=0},{name="air", prob=0, param2=0},{name="air", prob=0, param2=0},{name="air", prob=0, param2=0},{name="air", prob=0, param2=0},{name="air", prob=0, param2=0},{name="air", prob=0, param2=0},{name="air", prob=0, param2=0},{name="air", prob=0, param2=0},{name="air", prob=0, param2=0},{name="air", prob=0, param2=0},{name="air", prob=0, param2=0},{name="air", prob=0, param2=0},{name="air", prob=0, param2=0},{name="air", prob=0, param2=0},{name="air", prob=0, param2=0},{name="air", prob=0, param2=0},{name="air", prob=0, param2=0},{name="nodes:leaves", prob=214, param2=0},{name="nodes:leaves", prob=254, param2=0},{name="nodes:leaves", prob=254, param2=0},{name="nodes:leaves", prob=254, param2=0},{name="nodes:leaves", prob=214, param2=0},{name="nodes:leaves", prob=254, param2=0},{name="nodes:leaves", prob=254, param2=0},{name="nodes:leaves", prob=254, param2=0},{name="nodes:leaves", prob=254, param2=0},{name="nodes:leaves", prob=254, param2=0},{name="air", prob=0, param2=0},{name="nodes:leaves", prob=190, param2=0},{name="nodes:leaves", prob=254, param2=0},{name="nodes:leaves", prob=190, param2=0},{name="air", prob=0, param2=0},{name="air", prob=0, param2=0},{name="air", prob=0, param2=0},{name="nodes:leaves", prob=254, param2=0},{name="air", prob=0, param2=0},{name="air", prob=0, param2=0},{name="air", prob=0, param2=0},{name="air", prob=0, param2=0},{name="nodes:tree", prob=254, param2=0},{name="air", prob=0, param2=0},{name="air", prob=0, param2=0},{name="air", prob=0, param2=0},{name="air", prob=0, param2=0},{name="nodes:tree", prob=254, param2=0, force_place=true},{name="air", prob=0, param2=0},{name="air", prob=0, param2=0},{name="air", prob=0, param2=0},{name="air", prob=0, param2=0},{name="nodes:tree", prob=254, param2=0, force_place=true},{name="air", prob=0, param2=0},{name="air", prob=0, param2=0},{name="air", prob=0, param2=0},{name="air", prob=0, param2=0},{name="nodes:tree", prob=254, param2=0, force_place=true},{name="air", prob=0, param2=0},{name="air", prob=0, param2=0},{name="nodes:leaves", prob=254, param2=0},{name="nodes:leaves", prob=254, param2=0},{name="nodes:tree", prob=254, param2=0, force_place=true},{name="nodes:leaves", prob=254, param2=0},{name="nodes:leaves", prob=254, param2=0},{name="nodes:leaves", prob=254, param2=0},{name="nodes:leaves", prob=254, param2=0},{name="nodes:tree", prob=254, param2=0, force_place=true},{name="nodes:leaves", prob=254, param2=0},{name="nodes:leaves", prob=254, param2=0},{name="air", prob=0, param2=0},{name="nodes:leaves", prob=254, param2=0},{name="nodes:leaves", prob=254, param2=0},{name="nodes:leaves", prob=254, param2=0},{name="air", prob=0, param2=0},{name="air", prob=0, param2=0},{name="nodes:leaves", prob=254, param2=0},{name="nodes:leaves", prob=254, param2=0},{name="nodes:leaves", prob=254, param2=0},{name="air", prob=0, param2=0},{name="air", prob=0, param2=0},{name="air", prob=0, param2=0},{name="air", prob=0, param2=0},{name="air", prob=0, param2=0},{name="air", prob=0, param2=0},{name="air", prob=0, param2=0},{name="air", prob=0, param2=0},{name="air", prob=0, param2=0},{name="air", prob=0, param2=0},{name="air", prob=0, param2=0},{name="air", prob=0, param2=0},{name="air", prob=0, param2=0},{name="air", prob=0, param2=0},{name="air", prob=0, param2=0},{name="air", prob=0, param2=0},{name="air", prob=0, param2=0},{name="air", prob=0, param2=0},{name="air", prob=0, param2=0},{name="air", prob=0, param2=0},{name="air", prob=0, param2=0},{name="nodes:leaves", prob=214, param2=0},{name="nodes:leaves", prob=254, param2=0},{name="nodes:leaves", prob=254, param2=0},{name="nodes:leaves", prob=254, param2=0},{name="nodes:leaves", prob=214, param2=0},{name="nodes:leaves", prob=254, param2=0},{name="nodes:leaves", prob=254, param2=0},{name="nodes:leaves", prob=254, param2=0},{name="nodes:leaves", prob=254, param2=0},{name="nodes:leaves", prob=254, param2=0},{name="air", prob=0, param2=0},{name="nodes:leaves", prob=190, param2=0},{name="nodes:leaves", prob=254, param2=0},{name="nodes:leaves", prob=190, param2=0},{name="air", prob=0, param2=0},{name="air", prob=0, param2=0},{name="air", prob=0, param2=0},{name="nodes:leaves", prob=254, param2=0},{name="air", prob=0, param2=0},{name="air", prob=0, param2=0},{name="air", prob=0, param2=0},{name="air", prob=0, param2=0},{name="air", prob=0, param2=0},{name="air", prob=0, param2=0},{name="air", prob=0, param2=0},{name="air", prob=0, param2=0},{name="air", prob=0, param2=0},{name="air", prob=0, param2=0},{name="air", prob=0, param2=0},{name="air", prob=0, param2=0},{name="air", prob=0, param2=0},{name="air", prob=0, param2=0},{name="air", prob=0, param2=0},{name="air", prob=0, param2=0},{name="air", prob=0, param2=0},{name="air", prob=0, param2=0},{name="air", prob=0, param2=0},{name="air", prob=0, param2=0},{name="air", prob=0, param2=0},{name="air", prob=0, param2=0},{name="air", prob=0, param2=0},{name="nodes:leaves", prob=214, param2=0},{name="nodes:leaves", prob=254, param2=0},{name="nodes:leaves", prob=214, param2=0},{name="air", prob=0, param2=0},{name="air", prob=0, param2=0},{name="nodes:leaves", prob=254, param2=0},{name="nodes:leaves", prob=254, param2=0},{name="nodes:leaves", prob=254, param2=0},{name="air", prob=0, param2=0},{name="air", prob=0, param2=0},{name="air", prob=0, param2=0},{name="air", prob=0, param2=0},{name="air", prob=0, param2=0},{name="air", prob=0, param2=0},{name="air", prob=0, param2=0},{name="air", prob=0, param2=0},{name="air", prob=0, param2=0},{name="air", prob=0, param2=0},{name="air", prob=0, param2=0}
  },
}
